INFO:werkzeug:127.0.0.1 - - [17/Sep/2018 17:20:42] "GET /cars/insert HTTP/1.1" 200 -
INFO:werkzeug: * Running on http://127.0.0.1:5000/ (Press CTRL+C to quit)
INFO:werkzeug:127.0.0.1 - - [17/Sep/2018 17:21:09] "GET /cars/insert HTTP/1.1" 200 -
INFO:werkzeug:127.0.0.1 - - [17/Sep/2018 17:21:52] "GET /cars/insert HTTP/1.1" 200 -
INFO:werkzeug:127.0.0.1 - - [17/Sep/2018 17:21:55] "GET /cars/inserts HTTP/1.1" 404 -
INFO:werkzeug:127.0.0.1 - - [17/Sep/2018 17:22:09] "GET /cars/inserts HTTP/1.1" 404 -
INFO:werkzeug:127.0.0.1 - - [17/Sep/2018 17:22:13] "GET /cars/insert HTTP/1.1" 200 -
INFO:werkzeug: * Running on http://127.0.0.1:5000/ (Press CTRL+C to quit)
INFO:werkzeug: * Running on http://127.0.0.1:5000/ (Press CTRL+C to quit)
INFO:werkzeug:127.0.0.1 - - [17/Sep/2018 18:15:10] "GET / HTTP/1.1" 404 -
INFO:werkzeug:127.0.0.1 - - [17/Sep/2018 18:15:15] "GET / HTTP/1.1" 404 -
INFO:werkzeug:127.0.0.1 - - [17/Sep/2018 18:15:19] "GET /teste HTTP/1.1" 404 -
INFO:werkzeug:127.0.0.1 - - [17/Sep/2018 18:15:22] "GET /product HTTP/1.1" 200 -
INFO:werkzeug:127.0.0.1 - - [17/Sep/2018 18:15:22] "GET /products HTTP/1.1" 404 -
INFO:werkzeug:127.0.0.1 - - [17/Sep/2018 18:16:45] "GET /product HTTP/1.1" 200 -
INFO:werkzeug: * Running on http://127.0.0.1:5000/ (Press CTRL+C to quit)
INFO:werkzeug:127.0.0.1 - - [17/Sep/2018 18:16:48] "GET /product HTTP/1.1" 404 -
Level 3:werkzeug: * Running on http://127.0.0.1:5000/ (Press CTRL+C to quit)
Level 3:werkzeug:127.0.0.1 - - [17/Sep/2018 18:17:29] "GET /product HTTP/1.1" 404 -
WARNING:werkzeug: * Running on http://127.0.0.1:5000/ (Press CTRL+C to quit)
WARNING:werkzeug:127.0.0.1 - - [17/Sep/2018 18:18:04] "GET /product HTTP/1.1" 404 -
WARNING:werkzeug:127.0.0.1 - - [17/Sep/2018 18:18:12] "GET /product HTTP/1.1" 404 -
INFO:werkzeug: * Running on http://127.0.0.1:5000/ (Press CTRL+C to quit)
ERROR:flask.app:Exception on /product [GET]
Traceback (most recent call last):
  File "app.py", line 20, in route
    response = routing(request.method, controller, method, id, request.form)
  File "app.py", line 29, in routing
    return load_method(verb, controller, method, id, form)
  File "app.py", line 42, in load_method
    return getattr(controller, method)(verb, id, form)
TypeError: slice indices must be integers or None or have an __index__ method

During handling of the above exception, another exception occurred:

Traceback (most recent call last):
  File "/usr/local/lib/python3.5/dist-packages/flask/app.py", line 2292, in wsgi_app
    response = self.full_dispatch_request()
  File "/usr/local/lib/python3.5/dist-packages/flask/app.py", line 1815, in full_dispatch_request
    rv = self.handle_user_exception(e)
  File "/usr/local/lib/python3.5/dist-packages/flask/app.py", line 1718, in handle_user_exception
    reraise(exc_type, exc_value, tb)
  File "/usr/local/lib/python3.5/dist-packages/flask/_compat.py", line 35, in reraise
    raise value
  File "/usr/local/lib/python3.5/dist-packages/flask/app.py", line 1813, in full_dispatch_request
    rv = self.dispatch_request()
  File "/usr/local/lib/python3.5/dist-packages/flask/app.py", line 1799, in dispatch_request
    return self.view_functions[rule.endpoint](**req.view_args)
  File "app.py", line 24, in route
    logging.log('teset')
TypeError: log() missing 1 required positional argument: 'msg'
INFO:werkzeug:127.0.0.1 - - [17/Sep/2018 18:18:34] "GET /product HTTP/1.1" 500 -
ERROR:flask.app:Exception on /product/index [GET]
Traceback (most recent call last):
  File "app.py", line 20, in route
    response = routing(request.method, controller, method, id, request.form)
  File "app.py", line 29, in routing
    return load_method(verb, controller, method, id, form)
  File "app.py", line 42, in load_method
    return getattr(controller, method)(verb, id, form)
TypeError: slice indices must be integers or None or have an __index__ method

During handling of the above exception, another exception occurred:

Traceback (most recent call last):
  File "/usr/local/lib/python3.5/dist-packages/flask/app.py", line 2292, in wsgi_app
    response = self.full_dispatch_request()
  File "/usr/local/lib/python3.5/dist-packages/flask/app.py", line 1815, in full_dispatch_request
    rv = self.handle_user_exception(e)
  File "/usr/local/lib/python3.5/dist-packages/flask/app.py", line 1718, in handle_user_exception
    reraise(exc_type, exc_value, tb)
  File "/usr/local/lib/python3.5/dist-packages/flask/_compat.py", line 35, in reraise
    raise value
  File "/usr/local/lib/python3.5/dist-packages/flask/app.py", line 1813, in full_dispatch_request
    rv = self.dispatch_request()
  File "/usr/local/lib/python3.5/dist-packages/flask/app.py", line 1799, in dispatch_request
    return self.view_functions[rule.endpoint](**req.view_args)
  File "app.py", line 24, in route
    logging.log('teset')
TypeError: log() missing 1 required positional argument: 'msg'
INFO:werkzeug:127.0.0.1 - - [17/Sep/2018 18:19:07] "GET /product/index HTTP/1.1" 500 -
INFO:werkzeug: * Running on http://127.0.0.1:5000/ (Press CTRL+C to quit)
ERROR:flask.app:Exception on /product/index [GET]
Traceback (most recent call last):
  File "/usr/local/lib/python3.5/dist-packages/flask/app.py", line 2292, in wsgi_app
    response = self.full_dispatch_request()
  File "/usr/local/lib/python3.5/dist-packages/flask/app.py", line 1815, in full_dispatch_request
    rv = self.handle_user_exception(e)
  File "/usr/local/lib/python3.5/dist-packages/flask/app.py", line 1718, in handle_user_exception
    reraise(exc_type, exc_value, tb)
  File "/usr/local/lib/python3.5/dist-packages/flask/_compat.py", line 35, in reraise
    raise value
  File "/usr/local/lib/python3.5/dist-packages/flask/app.py", line 1813, in full_dispatch_request
    rv = self.dispatch_request()
  File "/usr/local/lib/python3.5/dist-packages/flask/app.py", line 1799, in dispatch_request
    return self.view_functions[rule.endpoint](**req.view_args)
  File "app.py", line 20, in route
    response = routing(request.method, controller, method, id, request.form)
  File "app.py", line 29, in routing
    return load_method(verb, controller, method, id, form)
  File "app.py", line 42, in load_method
    return getattr(controller, method)(verb, id, form)
TypeError: slice indices must be integers or None or have an __index__ method
INFO:werkzeug:127.0.0.1 - - [17/Sep/2018 18:19:38] "GET /product/index HTTP/1.1" 500 -
INFO:werkzeug: * Running on http://127.0.0.1:5000/ (Press CTRL+C to quit)
ERROR:flask.app:Exception on /product/index [GET]
Traceback (most recent call last):
  File "/usr/local/lib/python3.5/dist-packages/flask/app.py", line 2292, in wsgi_app
    response = self.full_dispatch_request()
  File "/usr/local/lib/python3.5/dist-packages/flask/app.py", line 1815, in full_dispatch_request
    rv = self.handle_user_exception(e)
  File "/usr/local/lib/python3.5/dist-packages/flask/app.py", line 1718, in handle_user_exception
    reraise(exc_type, exc_value, tb)
  File "/usr/local/lib/python3.5/dist-packages/flask/_compat.py", line 35, in reraise
    raise value
  File "/usr/local/lib/python3.5/dist-packages/flask/app.py", line 1813, in full_dispatch_request
    rv = self.dispatch_request()
  File "/usr/local/lib/python3.5/dist-packages/flask/app.py", line 1799, in dispatch_request
    return self.view_functions[rule.endpoint](**req.view_args)
  File "app.py", line 20, in route
    response = routing(request.method, controller, method, id, request.form)
  File "app.py", line 29, in routing
    return load_method(verb, controller, method, id, form)
  File "app.py", line 42, in load_method
    return getattr(controller, method)(verb, id, form)
TypeError: slice indices must be integers or None or have an __index__ method
INFO:werkzeug:127.0.0.1 - - [17/Sep/2018 18:20:51] "GET /product/index HTTP/1.1" 500 -
ERROR:flask.app:Exception on /product [GET]
Traceback (most recent call last):
  File "/usr/local/lib/python3.5/dist-packages/flask/app.py", line 2292, in wsgi_app
    response = self.full_dispatch_request()
  File "/usr/local/lib/python3.5/dist-packages/flask/app.py", line 1815, in full_dispatch_request
    rv = self.handle_user_exception(e)
  File "/usr/local/lib/python3.5/dist-packages/flask/app.py", line 1718, in handle_user_exception
    reraise(exc_type, exc_value, tb)
  File "/usr/local/lib/python3.5/dist-packages/flask/_compat.py", line 35, in reraise
    raise value
  File "/usr/local/lib/python3.5/dist-packages/flask/app.py", line 1813, in full_dispatch_request
    rv = self.dispatch_request()
  File "/usr/local/lib/python3.5/dist-packages/flask/app.py", line 1799, in dispatch_request
    return self.view_functions[rule.endpoint](**req.view_args)
  File "app.py", line 20, in route
    response = routing(request.method, controller, method, id, request.form)
  File "app.py", line 29, in routing
    return load_method(verb, controller, method, id, form)
  File "app.py", line 42, in load_method
    return getattr(controller, method)(verb, id, form)
TypeError: slice indices must be integers or None or have an __index__ method
INFO:werkzeug:127.0.0.1 - - [17/Sep/2018 18:20:54] "GET /product HTTP/1.1" 500 -
ERROR:flask.app:Exception on /product/index [GET]
Traceback (most recent call last):
  File "/usr/local/lib/python3.5/dist-packages/flask/app.py", line 2292, in wsgi_app
    response = self.full_dispatch_request()
  File "/usr/local/lib/python3.5/dist-packages/flask/app.py", line 1815, in full_dispatch_request
    rv = self.handle_user_exception(e)
  File "/usr/local/lib/python3.5/dist-packages/flask/app.py", line 1718, in handle_user_exception
    reraise(exc_type, exc_value, tb)
  File "/usr/local/lib/python3.5/dist-packages/flask/_compat.py", line 35, in reraise
    raise value
  File "/usr/local/lib/python3.5/dist-packages/flask/app.py", line 1813, in full_dispatch_request
    rv = self.dispatch_request()
  File "/usr/local/lib/python3.5/dist-packages/flask/app.py", line 1799, in dispatch_request
    return self.view_functions[rule.endpoint](**req.view_args)
  File "app.py", line 20, in route
    response = routing(request.method, controller, method, id, request.form)
  File "app.py", line 29, in routing
    return load_method(verb, controller, method, id, form)
  File "app.py", line 42, in load_method
    return getattr(controller, method)(verb, id, form)
TypeError: slice indices must be integers or None or have an __index__ method
INFO:werkzeug:127.0.0.1 - - [17/Sep/2018 18:20:56] "GET /product/index HTTP/1.1" 500 -
INFO:werkzeug:127.0.0.1 - - [17/Sep/2018 18:20:58] "GET /product/ HTTP/1.1" 404 -
INFO:werkzeug:127.0.0.1 - - [17/Sep/2018 18:21:01] "GET /product/index/ HTTP/1.1" 404 -
INFO:werkzeug:127.0.0.1 - - [17/Sep/2018 18:21:02] "GET /product/index/ HTTP/1.1" 404 -
ERROR:flask.app:Exception on /product/index [GET]
Traceback (most recent call last):
  File "/usr/local/lib/python3.5/dist-packages/flask/app.py", line 2292, in wsgi_app
    response = self.full_dispatch_request()
  File "/usr/local/lib/python3.5/dist-packages/flask/app.py", line 1815, in full_dispatch_request
    rv = self.handle_user_exception(e)
  File "/usr/local/lib/python3.5/dist-packages/flask/app.py", line 1718, in handle_user_exception
    reraise(exc_type, exc_value, tb)
  File "/usr/local/lib/python3.5/dist-packages/flask/_compat.py", line 35, in reraise
    raise value
  File "/usr/local/lib/python3.5/dist-packages/flask/app.py", line 1813, in full_dispatch_request
    rv = self.dispatch_request()
  File "/usr/local/lib/python3.5/dist-packages/flask/app.py", line 1799, in dispatch_request
    return self.view_functions[rule.endpoint](**req.view_args)
  File "app.py", line 20, in route
    response = routing(request.method, controller, method, id, request.form)
  File "app.py", line 29, in routing
    return load_method(verb, controller, method, id, form)
  File "app.py", line 42, in load_method
    return getattr(controller, method)(verb, id, form)
TypeError: slice indices must be integers or None or have an __index__ method
INFO:werkzeug:127.0.0.1 - - [17/Sep/2018 18:21:12] "GET /product/index HTTP/1.1" 500 -
INFO:werkzeug: * Running on http://127.0.0.1:5000/ (Press CTRL+C to quit)
ERROR:flask.app:Exception on /product/index [GET]
Traceback (most recent call last):
  File "/usr/local/lib/python3.5/dist-packages/flask/app.py", line 2292, in wsgi_app
    response = self.full_dispatch_request()
  File "/usr/local/lib/python3.5/dist-packages/flask/app.py", line 1815, in full_dispatch_request
    rv = self.handle_user_exception(e)
  File "/usr/local/lib/python3.5/dist-packages/flask/app.py", line 1718, in handle_user_exception
    reraise(exc_type, exc_value, tb)
  File "/usr/local/lib/python3.5/dist-packages/flask/_compat.py", line 35, in reraise
    raise value
  File "/usr/local/lib/python3.5/dist-packages/flask/app.py", line 1813, in full_dispatch_request
    rv = self.dispatch_request()
  File "/usr/local/lib/python3.5/dist-packages/flask/app.py", line 1799, in dispatch_request
    return self.view_functions[rule.endpoint](**req.view_args)
  File "app.py", line 20, in route
    response = routing(request.method, controller, method, id, request.form)
  File "app.py", line 29, in routing
    return load_method(verb, controller, method, id, form=None)
  File "app.py", line 42, in load_method
    return getattr(controller, method)(verb, id, form)
ValueError: substring not found
INFO:werkzeug:127.0.0.1 - - [17/Sep/2018 18:21:53] "GET /product/index HTTP/1.1" 500 -
ERROR:flask.app:Exception on /product/index [GET]
Traceback (most recent call last):
  File "/usr/local/lib/python3.5/dist-packages/flask/app.py", line 2292, in wsgi_app
    response = self.full_dispatch_request()
  File "/usr/local/lib/python3.5/dist-packages/flask/app.py", line 1815, in full_dispatch_request
    rv = self.handle_user_exception(e)
  File "/usr/local/lib/python3.5/dist-packages/flask/app.py", line 1718, in handle_user_exception
    reraise(exc_type, exc_value, tb)
  File "/usr/local/lib/python3.5/dist-packages/flask/_compat.py", line 35, in reraise
    raise value
  File "/usr/local/lib/python3.5/dist-packages/flask/app.py", line 1813, in full_dispatch_request
    rv = self.dispatch_request()
  File "/usr/local/lib/python3.5/dist-packages/flask/app.py", line 1799, in dispatch_request
    return self.view_functions[rule.endpoint](**req.view_args)
  File "app.py", line 20, in route
    response = routing(request.method, controller, method, id, request.form)
  File "app.py", line 29, in routing
    return load_method(verb, controller, method, id, form=None)
  File "app.py", line 42, in load_method
    return getattr(controller, method)(verb, id, form)
ValueError: substring not found
INFO:werkzeug:127.0.0.1 - - [17/Sep/2018 18:21:54] "GET /product/index HTTP/1.1" 500 -
INFO:werkzeug: * Running on http://127.0.0.1:5000/ (Press CTRL+C to quit)
ERROR:flask.app:Exception on /product/index [GET]
Traceback (most recent call last):
  File "app.py", line 20, in route
    response = routing(request.method, controller, method, id, request.form)
  File "app.py", line 29, in routing
    return load_method(verb, controller, method, id, form)
  File "app.py", line 42, in load_method
    return getattr(controller, method)(verb, id, form)
TypeError: slice indices must be integers or None or have an __index__ method

During handling of the above exception, another exception occurred:

Traceback (most recent call last):
  File "/usr/local/lib/python3.5/dist-packages/flask/app.py", line 2292, in wsgi_app
    response = self.full_dispatch_request()
  File "/usr/local/lib/python3.5/dist-packages/flask/app.py", line 1815, in full_dispatch_request
    rv = self.handle_user_exception(e)
  File "/usr/local/lib/python3.5/dist-packages/flask/app.py", line 1718, in handle_user_exception
    reraise(exc_type, exc_value, tb)
  File "/usr/local/lib/python3.5/dist-packages/flask/_compat.py", line 35, in reraise
    raise value
  File "/usr/local/lib/python3.5/dist-packages/flask/app.py", line 1813, in full_dispatch_request
    rv = self.dispatch_request()
  File "/usr/local/lib/python3.5/dist-packages/flask/app.py", line 1799, in dispatch_request
    return self.view_functions[rule.endpoint](**req.view_args)
  File "app.py", line 24, in route
    logging.log('teset')
TypeError: log() missing 1 required positional argument: 'msg'
INFO:werkzeug:127.0.0.1 - - [17/Sep/2018 18:22:11] "GET /product/index HTTP/1.1" 500 -
ERROR:flask.app:Exception on /product/index [GET]
Traceback (most recent call last):
  File "app.py", line 20, in route
    response = routing(request.method, controller, method, id, request.form)
  File "app.py", line 29, in routing
    return load_method(verb, controller, method, id, form)
  File "app.py", line 42, in load_method
    return getattr(controller, method)(verb, id, form)
TypeError: slice indices must be integers or None or have an __index__ method

During handling of the above exception, another exception occurred:

Traceback (most recent call last):
  File "/usr/local/lib/python3.5/dist-packages/flask/app.py", line 2292, in wsgi_app
    response = self.full_dispatch_request()
  File "/usr/local/lib/python3.5/dist-packages/flask/app.py", line 1815, in full_dispatch_request
    rv = self.handle_user_exception(e)
  File "/usr/local/lib/python3.5/dist-packages/flask/app.py", line 1718, in handle_user_exception
    reraise(exc_type, exc_value, tb)
  File "/usr/local/lib/python3.5/dist-packages/flask/_compat.py", line 35, in reraise
    raise value
  File "/usr/local/lib/python3.5/dist-packages/flask/app.py", line 1813, in full_dispatch_request
    rv = self.dispatch_request()
  File "/usr/local/lib/python3.5/dist-packages/flask/app.py", line 1799, in dispatch_request
    return self.view_functions[rule.endpoint](**req.view_args)
  File "app.py", line 24, in route
    logging.log('teset')
TypeError: log() missing 1 required positional argument: 'msg'
INFO:werkzeug:127.0.0.1 - - [17/Sep/2018 18:22:11] "GET /product/index HTTP/1.1" 500 -
ERROR:flask.app:Exception on /product/index [GET]
Traceback (most recent call last):
  File "app.py", line 20, in route
    response = routing(request.method, controller, method, id, request.form)
  File "app.py", line 29, in routing
    return load_method(verb, controller, method, id, form)
  File "app.py", line 42, in load_method
    return getattr(controller, method)(verb, id, form)
TypeError: slice indices must be integers or None or have an __index__ method

During handling of the above exception, another exception occurred:

Traceback (most recent call last):
  File "/usr/local/lib/python3.5/dist-packages/flask/app.py", line 2292, in wsgi_app
    response = self.full_dispatch_request()
  File "/usr/local/lib/python3.5/dist-packages/flask/app.py", line 1815, in full_dispatch_request
    rv = self.handle_user_exception(e)
  File "/usr/local/lib/python3.5/dist-packages/flask/app.py", line 1718, in handle_user_exception
    reraise(exc_type, exc_value, tb)
  File "/usr/local/lib/python3.5/dist-packages/flask/_compat.py", line 35, in reraise
    raise value
  File "/usr/local/lib/python3.5/dist-packages/flask/app.py", line 1813, in full_dispatch_request
    rv = self.dispatch_request()
  File "/usr/local/lib/python3.5/dist-packages/flask/app.py", line 1799, in dispatch_request
    return self.view_functions[rule.endpoint](**req.view_args)
  File "app.py", line 24, in route
    logging.log('teset')
TypeError: log() missing 1 required positional argument: 'msg'
INFO:werkzeug:127.0.0.1 - - [17/Sep/2018 18:22:11] "GET /product/index HTTP/1.1" 500 -
ERROR:flask.app:Exception on /product/index [GET]
Traceback (most recent call last):
  File "app.py", line 20, in route
    response = routing(request.method, controller, method, id, request.form)
  File "app.py", line 29, in routing
    return load_method(verb, controller, method, id, form)
  File "app.py", line 42, in load_method
    return getattr(controller, method)(verb, id, form)
TypeError: slice indices must be integers or None or have an __index__ method

During handling of the above exception, another exception occurred:

Traceback (most recent call last):
  File "/usr/local/lib/python3.5/dist-packages/flask/app.py", line 2292, in wsgi_app
    response = self.full_dispatch_request()
  File "/usr/local/lib/python3.5/dist-packages/flask/app.py", line 1815, in full_dispatch_request
    rv = self.handle_user_exception(e)
  File "/usr/local/lib/python3.5/dist-packages/flask/app.py", line 1718, in handle_user_exception
    reraise(exc_type, exc_value, tb)
  File "/usr/local/lib/python3.5/dist-packages/flask/_compat.py", line 35, in reraise
    raise value
  File "/usr/local/lib/python3.5/dist-packages/flask/app.py", line 1813, in full_dispatch_request
    rv = self.dispatch_request()
  File "/usr/local/lib/python3.5/dist-packages/flask/app.py", line 1799, in dispatch_request
    return self.view_functions[rule.endpoint](**req.view_args)
  File "app.py", line 24, in route
    logging.log('teset')
TypeError: log() missing 1 required positional argument: 'msg'
INFO:werkzeug:127.0.0.1 - - [17/Sep/2018 18:22:11] "GET /product/index HTTP/1.1" 500 -
ERROR:flask.app:Exception on /product [GET]
Traceback (most recent call last):
  File "app.py", line 20, in route
    response = routing(request.method, controller, method, id, request.form)
  File "app.py", line 29, in routing
    return load_method(verb, controller, method, id, form)
  File "app.py", line 42, in load_method
    return getattr(controller, method)(verb, id, form)
TypeError: slice indices must be integers or None or have an __index__ method

During handling of the above exception, another exception occurred:

Traceback (most recent call last):
  File "/usr/local/lib/python3.5/dist-packages/flask/app.py", line 2292, in wsgi_app
    response = self.full_dispatch_request()
  File "/usr/local/lib/python3.5/dist-packages/flask/app.py", line 1815, in full_dispatch_request
    rv = self.handle_user_exception(e)
  File "/usr/local/lib/python3.5/dist-packages/flask/app.py", line 1718, in handle_user_exception
    reraise(exc_type, exc_value, tb)
  File "/usr/local/lib/python3.5/dist-packages/flask/_compat.py", line 35, in reraise
    raise value
  File "/usr/local/lib/python3.5/dist-packages/flask/app.py", line 1813, in full_dispatch_request
    rv = self.dispatch_request()
  File "/usr/local/lib/python3.5/dist-packages/flask/app.py", line 1799, in dispatch_request
    return self.view_functions[rule.endpoint](**req.view_args)
  File "app.py", line 24, in route
    logging.log('teset')
TypeError: log() missing 1 required positional argument: 'msg'
INFO:werkzeug:127.0.0.1 - - [17/Sep/2018 18:22:15] "GET /product HTTP/1.1" 500 -
INFO:werkzeug: * Running on http://127.0.0.1:5000/ (Press CTRL+C to quit)
INFO:werkzeug:127.0.0.1 - - [17/Sep/2018 18:22:32] "GET /product HTTP/1.1" 200 -
INFO:werkzeug:127.0.0.1 - - [17/Sep/2018 18:22:49] "GET /product/index HTTP/1.1" 200 -
INFO:werkzeug:127.0.0.1 - - [17/Sep/2018 18:23:10] "GET /product/index HTTP/1.1" 200 -
INFO:werkzeug: * Running on http://127.0.0.1:5000/ (Press CTRL+C to quit)
ERROR:flask.app:Exception on /product/index [GET]
Traceback (most recent call last):
  File "app.py", line 21, in route
    return jsonify(response), 200
  File "/usr/local/lib/python3.5/dist-packages/flask/json/__init__.py", line 321, in jsonify
    dumps(data, indent=indent, separators=separators) + '\n',
  File "/usr/local/lib/python3.5/dist-packages/flask/json/__init__.py", line 179, in dumps
    rv = _json.dumps(obj, **kwargs)
  File "/usr/lib/python3.5/json/__init__.py", line 237, in dumps
    **kw).encode(obj)
  File "/usr/lib/python3.5/json/encoder.py", line 198, in encode
    chunks = self.iterencode(o, _one_shot=True)
  File "/usr/lib/python3.5/json/encoder.py", line 256, in iterencode
    return _iterencode(o, 0)
  File "/usr/local/lib/python3.5/dist-packages/flask/json/__init__.py", line 81, in default
    return _json.JSONEncoder.default(self, o)
  File "/usr/lib/python3.5/json/encoder.py", line 179, in default
    raise TypeError(repr(o) + " is not JSON serializable")
TypeError: <Response 16 bytes [200 OK]> is not JSON serializable

During handling of the above exception, another exception occurred:

Traceback (most recent call last):
  File "/usr/local/lib/python3.5/dist-packages/flask/app.py", line 2292, in wsgi_app
    response = self.full_dispatch_request()
  File "/usr/local/lib/python3.5/dist-packages/flask/app.py", line 1815, in full_dispatch_request
    rv = self.handle_user_exception(e)
  File "/usr/local/lib/python3.5/dist-packages/flask/app.py", line 1718, in handle_user_exception
    reraise(exc_type, exc_value, tb)
  File "/usr/local/lib/python3.5/dist-packages/flask/_compat.py", line 35, in reraise
    raise value
  File "/usr/local/lib/python3.5/dist-packages/flask/app.py", line 1813, in full_dispatch_request
    rv = self.dispatch_request()
  File "/usr/local/lib/python3.5/dist-packages/flask/app.py", line 1799, in dispatch_request
    return self.view_functions[rule.endpoint](**req.view_args)
  File "app.py", line 24, in route
    logging.log('teset')
TypeError: log() missing 1 required positional argument: 'msg'
INFO:werkzeug:127.0.0.1 - - [17/Sep/2018 18:23:13] "GET /product/index HTTP/1.1" 500 -
INFO:werkzeug: * Running on http://127.0.0.1:5000/ (Press CTRL+C to quit)
ERROR:flask.app:Exception on /product/index [GET]
Traceback (most recent call last):
  File "/usr/local/lib/python3.5/dist-packages/flask/app.py", line 2292, in wsgi_app
    response = self.full_dispatch_request()
  File "/usr/local/lib/python3.5/dist-packages/flask/app.py", line 1815, in full_dispatch_request
    rv = self.handle_user_exception(e)
  File "/usr/local/lib/python3.5/dist-packages/flask/app.py", line 1718, in handle_user_exception
    reraise(exc_type, exc_value, tb)
  File "/usr/local/lib/python3.5/dist-packages/flask/_compat.py", line 35, in reraise
    raise value
  File "/usr/local/lib/python3.5/dist-packages/flask/app.py", line 1813, in full_dispatch_request
    rv = self.dispatch_request()
  File "/usr/local/lib/python3.5/dist-packages/flask/app.py", line 1799, in dispatch_request
    return self.view_functions[rule.endpoint](**req.view_args)
  File "app.py", line 21, in route
    return jsonify(response), 200
  File "/usr/local/lib/python3.5/dist-packages/flask/json/__init__.py", line 321, in jsonify
    dumps(data, indent=indent, separators=separators) + '\n',
  File "/usr/local/lib/python3.5/dist-packages/flask/json/__init__.py", line 179, in dumps
    rv = _json.dumps(obj, **kwargs)
  File "/usr/lib/python3.5/json/__init__.py", line 237, in dumps
    **kw).encode(obj)
  File "/usr/lib/python3.5/json/encoder.py", line 198, in encode
    chunks = self.iterencode(o, _one_shot=True)
  File "/usr/lib/python3.5/json/encoder.py", line 256, in iterencode
    return _iterencode(o, 0)
  File "/usr/local/lib/python3.5/dist-packages/flask/json/__init__.py", line 81, in default
    return _json.JSONEncoder.default(self, o)
  File "/usr/lib/python3.5/json/encoder.py", line 179, in default
    raise TypeError(repr(o) + " is not JSON serializable")
TypeError: <Response 16 bytes [200 OK]> is not JSON serializable
INFO:werkzeug:127.0.0.1 - - [17/Sep/2018 18:23:42] "GET /product/index HTTP/1.1" 500 -
INFO:werkzeug: * Running on http://127.0.0.1:5000/ (Press CTRL+C to quit)
ERROR:flask.app:Exception on /product/index [GET]
Traceback (most recent call last):
  File "/usr/local/lib/python3.5/dist-packages/flask/app.py", line 2292, in wsgi_app
    response = self.full_dispatch_request()
  File "/usr/local/lib/python3.5/dist-packages/flask/app.py", line 1815, in full_dispatch_request
    rv = self.handle_user_exception(e)
  File "/usr/local/lib/python3.5/dist-packages/flask/app.py", line 1718, in handle_user_exception
    reraise(exc_type, exc_value, tb)
  File "/usr/local/lib/python3.5/dist-packages/flask/_compat.py", line 35, in reraise
    raise value
  File "/usr/local/lib/python3.5/dist-packages/flask/app.py", line 1813, in full_dispatch_request
    rv = self.dispatch_request()
  File "/usr/local/lib/python3.5/dist-packages/flask/app.py", line 1799, in dispatch_request
    return self.view_functions[rule.endpoint](**req.view_args)
  File "app.py", line 21, in route
    return jsonify(response), 200
  File "/usr/local/lib/python3.5/dist-packages/flask/json/__init__.py", line 321, in jsonify
    dumps(data, indent=indent, separators=separators) + '\n',
  File "/usr/local/lib/python3.5/dist-packages/flask/json/__init__.py", line 179, in dumps
    rv = _json.dumps(obj, **kwargs)
  File "/usr/lib/python3.5/json/__init__.py", line 237, in dumps
    **kw).encode(obj)
  File "/usr/lib/python3.5/json/encoder.py", line 198, in encode
    chunks = self.iterencode(o, _one_shot=True)
  File "/usr/lib/python3.5/json/encoder.py", line 256, in iterencode
    return _iterencode(o, 0)
  File "/usr/local/lib/python3.5/dist-packages/flask/json/__init__.py", line 81, in default
    return _json.JSONEncoder.default(self, o)
  File "/usr/lib/python3.5/json/encoder.py", line 179, in default
    raise TypeError(repr(o) + " is not JSON serializable")
TypeError: <Response 13 bytes [200 OK]> is not JSON serializable
INFO:werkzeug:127.0.0.1 - - [17/Sep/2018 18:24:04] "GET /product/index HTTP/1.1" 500 -
ERROR:flask.app:Exception on /product/index [GET]
Traceback (most recent call last):
  File "/usr/local/lib/python3.5/dist-packages/flask/app.py", line 2292, in wsgi_app
    response = self.full_dispatch_request()
  File "/usr/local/lib/python3.5/dist-packages/flask/app.py", line 1815, in full_dispatch_request
    rv = self.handle_user_exception(e)
  File "/usr/local/lib/python3.5/dist-packages/flask/app.py", line 1718, in handle_user_exception
    reraise(exc_type, exc_value, tb)
  File "/usr/local/lib/python3.5/dist-packages/flask/_compat.py", line 35, in reraise
    raise value
  File "/usr/local/lib/python3.5/dist-packages/flask/app.py", line 1813, in full_dispatch_request
    rv = self.dispatch_request()
  File "/usr/local/lib/python3.5/dist-packages/flask/app.py", line 1799, in dispatch_request
    return self.view_functions[rule.endpoint](**req.view_args)
  File "app.py", line 21, in route
    return jsonify(response), 200
  File "/usr/local/lib/python3.5/dist-packages/flask/json/__init__.py", line 321, in jsonify
    dumps(data, indent=indent, separators=separators) + '\n',
  File "/usr/local/lib/python3.5/dist-packages/flask/json/__init__.py", line 179, in dumps
    rv = _json.dumps(obj, **kwargs)
  File "/usr/lib/python3.5/json/__init__.py", line 237, in dumps
    **kw).encode(obj)
  File "/usr/lib/python3.5/json/encoder.py", line 198, in encode
    chunks = self.iterencode(o, _one_shot=True)
  File "/usr/lib/python3.5/json/encoder.py", line 256, in iterencode
    return _iterencode(o, 0)
  File "/usr/local/lib/python3.5/dist-packages/flask/json/__init__.py", line 81, in default
    return _json.JSONEncoder.default(self, o)
  File "/usr/lib/python3.5/json/encoder.py", line 179, in default
    raise TypeError(repr(o) + " is not JSON serializable")
TypeError: <Response 13 bytes [200 OK]> is not JSON serializable
INFO:werkzeug:127.0.0.1 - - [17/Sep/2018 18:24:04] "GET /product/index HTTP/1.1" 500 -
ERROR:flask.app:Exception on /product/index [GET]
Traceback (most recent call last):
  File "/usr/local/lib/python3.5/dist-packages/flask/app.py", line 2292, in wsgi_app
    response = self.full_dispatch_request()
  File "/usr/local/lib/python3.5/dist-packages/flask/app.py", line 1815, in full_dispatch_request
    rv = self.handle_user_exception(e)
  File "/usr/local/lib/python3.5/dist-packages/flask/app.py", line 1718, in handle_user_exception
    reraise(exc_type, exc_value, tb)
  File "/usr/local/lib/python3.5/dist-packages/flask/_compat.py", line 35, in reraise
    raise value
  File "/usr/local/lib/python3.5/dist-packages/flask/app.py", line 1813, in full_dispatch_request
    rv = self.dispatch_request()
  File "/usr/local/lib/python3.5/dist-packages/flask/app.py", line 1799, in dispatch_request
    return self.view_functions[rule.endpoint](**req.view_args)
  File "app.py", line 21, in route
    return jsonify(response), 200
  File "/usr/local/lib/python3.5/dist-packages/flask/json/__init__.py", line 321, in jsonify
    dumps(data, indent=indent, separators=separators) + '\n',
  File "/usr/local/lib/python3.5/dist-packages/flask/json/__init__.py", line 179, in dumps
    rv = _json.dumps(obj, **kwargs)
  File "/usr/lib/python3.5/json/__init__.py", line 237, in dumps
    **kw).encode(obj)
  File "/usr/lib/python3.5/json/encoder.py", line 198, in encode
    chunks = self.iterencode(o, _one_shot=True)
  File "/usr/lib/python3.5/json/encoder.py", line 256, in iterencode
    return _iterencode(o, 0)
  File "/usr/local/lib/python3.5/dist-packages/flask/json/__init__.py", line 81, in default
    return _json.JSONEncoder.default(self, o)
  File "/usr/lib/python3.5/json/encoder.py", line 179, in default
    raise TypeError(repr(o) + " is not JSON serializable")
TypeError: <Response 13 bytes [200 OK]> is not JSON serializable
INFO:werkzeug:127.0.0.1 - - [17/Sep/2018 18:24:04] "GET /product/index HTTP/1.1" 500 -
ERROR:flask.app:Exception on /product/index [GET]
Traceback (most recent call last):
  File "/usr/local/lib/python3.5/dist-packages/flask/app.py", line 2292, in wsgi_app
    response = self.full_dispatch_request()
  File "/usr/local/lib/python3.5/dist-packages/flask/app.py", line 1815, in full_dispatch_request
    rv = self.handle_user_exception(e)
  File "/usr/local/lib/python3.5/dist-packages/flask/app.py", line 1718, in handle_user_exception
    reraise(exc_type, exc_value, tb)
  File "/usr/local/lib/python3.5/dist-packages/flask/_compat.py", line 35, in reraise
    raise value
  File "/usr/local/lib/python3.5/dist-packages/flask/app.py", line 1813, in full_dispatch_request
    rv = self.dispatch_request()
  File "/usr/local/lib/python3.5/dist-packages/flask/app.py", line 1799, in dispatch_request
    return self.view_functions[rule.endpoint](**req.view_args)
  File "app.py", line 21, in route
    return jsonify(response), 200
  File "/usr/local/lib/python3.5/dist-packages/flask/json/__init__.py", line 321, in jsonify
    dumps(data, indent=indent, separators=separators) + '\n',
  File "/usr/local/lib/python3.5/dist-packages/flask/json/__init__.py", line 179, in dumps
    rv = _json.dumps(obj, **kwargs)
  File "/usr/lib/python3.5/json/__init__.py", line 237, in dumps
    **kw).encode(obj)
  File "/usr/lib/python3.5/json/encoder.py", line 198, in encode
    chunks = self.iterencode(o, _one_shot=True)
  File "/usr/lib/python3.5/json/encoder.py", line 256, in iterencode
    return _iterencode(o, 0)
  File "/usr/local/lib/python3.5/dist-packages/flask/json/__init__.py", line 81, in default
    return _json.JSONEncoder.default(self, o)
  File "/usr/lib/python3.5/json/encoder.py", line 179, in default
    raise TypeError(repr(o) + " is not JSON serializable")
TypeError: <Response 13 bytes [200 OK]> is not JSON serializable
INFO:werkzeug:127.0.0.1 - - [17/Sep/2018 18:24:04] "GET /product/index HTTP/1.1" 500 -
INFO:werkzeug: * Running on http://127.0.0.1:5000/ (Press CTRL+C to quit)
INFO:werkzeug:127.0.0.1 - - [17/Sep/2018 18:24:19] "GET /product/index HTTP/1.1" 200 -
INFO:werkzeug: * Running on http://127.0.0.1:5000/ (Press CTRL+C to quit)
INFO:werkzeug:127.0.0.1 - - [17/Sep/2018 18:24:31] "GET /product/index HTTP/1.1" 200 -
INFO:werkzeug: * Running on http://127.0.0.1:5000/ (Press CTRL+C to quit)
INFO:werkzeug:127.0.0.1 - - [17/Sep/2018 18:24:40] "GET /product/index HTTP/1.1" 200 -
INFO:werkzeug: * Running on http://127.0.0.1:5000/ (Press CTRL+C to quit)
ERROR:flask.app:Exception on /product/index [GET]
Traceback (most recent call last):
  File "/usr/local/lib/python3.5/dist-packages/flask/app.py", line 2292, in wsgi_app
    response = self.full_dispatch_request()
  File "/usr/local/lib/python3.5/dist-packages/flask/app.py", line 1815, in full_dispatch_request
    rv = self.handle_user_exception(e)
  File "/usr/local/lib/python3.5/dist-packages/flask/app.py", line 1718, in handle_user_exception
    reraise(exc_type, exc_value, tb)
  File "/usr/local/lib/python3.5/dist-packages/flask/_compat.py", line 35, in reraise
    raise value
  File "/usr/local/lib/python3.5/dist-packages/flask/app.py", line 1813, in full_dispatch_request
    rv = self.dispatch_request()
  File "/usr/local/lib/python3.5/dist-packages/flask/app.py", line 1799, in dispatch_request
    return self.view_functions[rule.endpoint](**req.view_args)
  File "app.py", line 20, in route
    response = routing(request.method, controller, method, id, request.form)
  File "app.py", line 28, in routing
    return load_method(verb, controller, method, id, form)
  File "app.py", line 41, in load_method
    return getattr(controller, method)(verb, id, form)
  File "/home/fabio/www/python/controller/product.py", line 4, in index
    return jsonify({verb, id, form})
  File "/usr/local/lib/python3.5/dist-packages/flask/json/__init__.py", line 321, in jsonify
    dumps(data, indent=indent, separators=separators) + '\n',
  File "/usr/local/lib/python3.5/dist-packages/flask/json/__init__.py", line 179, in dumps
    rv = _json.dumps(obj, **kwargs)
  File "/usr/lib/python3.5/json/__init__.py", line 237, in dumps
    **kw).encode(obj)
  File "/usr/lib/python3.5/json/encoder.py", line 198, in encode
    chunks = self.iterencode(o, _one_shot=True)
  File "/usr/lib/python3.5/json/encoder.py", line 256, in iterencode
    return _iterencode(o, 0)
  File "/usr/local/lib/python3.5/dist-packages/flask/json/__init__.py", line 81, in default
    return _json.JSONEncoder.default(self, o)
  File "/usr/lib/python3.5/json/encoder.py", line 179, in default
    raise TypeError(repr(o) + " is not JSON serializable")
TypeError: {'GET', ImmutableMultiDict([]), None} is not JSON serializable
INFO:werkzeug:127.0.0.1 - - [17/Sep/2018 18:24:58] "GET /product/index HTTP/1.1" 500 -
INFO:werkzeug: * Running on http://127.0.0.1:5000/ (Press CTRL+C to quit)
ERROR:flask.app:Exception on /product/index [GET]
Traceback (most recent call last):
  File "/usr/local/lib/python3.5/dist-packages/flask/app.py", line 2292, in wsgi_app
    response = self.full_dispatch_request()
  File "/usr/local/lib/python3.5/dist-packages/flask/app.py", line 1815, in full_dispatch_request
    rv = self.handle_user_exception(e)
  File "/usr/local/lib/python3.5/dist-packages/flask/app.py", line 1718, in handle_user_exception
    reraise(exc_type, exc_value, tb)
  File "/usr/local/lib/python3.5/dist-packages/flask/_compat.py", line 35, in reraise
    raise value
  File "/usr/local/lib/python3.5/dist-packages/flask/app.py", line 1813, in full_dispatch_request
    rv = self.dispatch_request()
  File "/usr/local/lib/python3.5/dist-packages/flask/app.py", line 1799, in dispatch_request
    return self.view_functions[rule.endpoint](**req.view_args)
  File "app.py", line 20, in route
    response = routing(request.method, controller, method, id, request.form)
  File "app.py", line 28, in routing
    return load_method(verb, controller, method, id, form)
  File "app.py", line 41, in load_method
    return getattr(controller, method)(verb, id, form)
  File "/home/fabio/www/python/controller/product.py", line 4, in index
    return jsonify({verb, id, form})
  File "/usr/local/lib/python3.5/dist-packages/flask/json/__init__.py", line 321, in jsonify
    dumps(data, indent=indent, separators=separators) + '\n',
  File "/usr/local/lib/python3.5/dist-packages/flask/json/__init__.py", line 179, in dumps
    rv = _json.dumps(obj, **kwargs)
  File "/usr/lib/python3.5/json/__init__.py", line 237, in dumps
    **kw).encode(obj)
  File "/usr/lib/python3.5/json/encoder.py", line 198, in encode
    chunks = self.iterencode(o, _one_shot=True)
  File "/usr/lib/python3.5/json/encoder.py", line 256, in iterencode
    return _iterencode(o, 0)
  File "/usr/local/lib/python3.5/dist-packages/flask/json/__init__.py", line 81, in default
    return _json.JSONEncoder.default(self, o)
  File "/usr/lib/python3.5/json/encoder.py", line 179, in default
    raise TypeError(repr(o) + " is not JSON serializable")
TypeError: {ImmutableMultiDict([]), None, 'GET'} is not JSON serializable
INFO:werkzeug:127.0.0.1 - - [17/Sep/2018 18:26:04] "GET /product/index HTTP/1.1" 500 -
ERROR:flask.app:Exception on /product/index [GET]
Traceback (most recent call last):
  File "/usr/local/lib/python3.5/dist-packages/flask/app.py", line 2292, in wsgi_app
    response = self.full_dispatch_request()
  File "/usr/local/lib/python3.5/dist-packages/flask/app.py", line 1815, in full_dispatch_request
    rv = self.handle_user_exception(e)
  File "/usr/local/lib/python3.5/dist-packages/flask/app.py", line 1718, in handle_user_exception
    reraise(exc_type, exc_value, tb)
  File "/usr/local/lib/python3.5/dist-packages/flask/_compat.py", line 35, in reraise
    raise value
  File "/usr/local/lib/python3.5/dist-packages/flask/app.py", line 1813, in full_dispatch_request
    rv = self.dispatch_request()
  File "/usr/local/lib/python3.5/dist-packages/flask/app.py", line 1799, in dispatch_request
    return self.view_functions[rule.endpoint](**req.view_args)
  File "app.py", line 20, in route
    response = routing(request.method, controller, method, id, request.form)
  File "app.py", line 28, in routing
    return load_method(verb, controller, method, id, form)
  File "app.py", line 41, in load_method
    return getattr(controller, method)(verb, id, form)
  File "/home/fabio/www/python/controller/product.py", line 4, in index
    return jsonify({verb, id, form})
  File "/usr/local/lib/python3.5/dist-packages/flask/json/__init__.py", line 321, in jsonify
    dumps(data, indent=indent, separators=separators) + '\n',
  File "/usr/local/lib/python3.5/dist-packages/flask/json/__init__.py", line 179, in dumps
    rv = _json.dumps(obj, **kwargs)
  File "/usr/lib/python3.5/json/__init__.py", line 237, in dumps
    **kw).encode(obj)
  File "/usr/lib/python3.5/json/encoder.py", line 198, in encode
    chunks = self.iterencode(o, _one_shot=True)
  File "/usr/lib/python3.5/json/encoder.py", line 256, in iterencode
    return _iterencode(o, 0)
  File "/usr/local/lib/python3.5/dist-packages/flask/json/__init__.py", line 81, in default
    return _json.JSONEncoder.default(self, o)
  File "/usr/lib/python3.5/json/encoder.py", line 179, in default
    raise TypeError(repr(o) + " is not JSON serializable")
TypeError: {ImmutableMultiDict([]), None, 'GET'} is not JSON serializable
INFO:werkzeug:127.0.0.1 - - [17/Sep/2018 18:26:05] "GET /product/index HTTP/1.1" 500 -
ERROR:flask.app:Exception on /product/index [GET]
Traceback (most recent call last):
  File "/usr/local/lib/python3.5/dist-packages/flask/app.py", line 2292, in wsgi_app
    response = self.full_dispatch_request()
  File "/usr/local/lib/python3.5/dist-packages/flask/app.py", line 1815, in full_dispatch_request
    rv = self.handle_user_exception(e)
  File "/usr/local/lib/python3.5/dist-packages/flask/app.py", line 1718, in handle_user_exception
    reraise(exc_type, exc_value, tb)
  File "/usr/local/lib/python3.5/dist-packages/flask/_compat.py", line 35, in reraise
    raise value
  File "/usr/local/lib/python3.5/dist-packages/flask/app.py", line 1813, in full_dispatch_request
    rv = self.dispatch_request()
  File "/usr/local/lib/python3.5/dist-packages/flask/app.py", line 1799, in dispatch_request
    return self.view_functions[rule.endpoint](**req.view_args)
  File "app.py", line 20, in route
    response = routing(request.method, controller, method, id, request.form)
  File "app.py", line 28, in routing
    return load_method(verb, controller, method, id, form)
  File "app.py", line 41, in load_method
    return getattr(controller, method)(verb, id, form)
  File "/home/fabio/www/python/controller/product.py", line 4, in index
    return jsonify({verb, id, form})
  File "/usr/local/lib/python3.5/dist-packages/flask/json/__init__.py", line 321, in jsonify
    dumps(data, indent=indent, separators=separators) + '\n',
  File "/usr/local/lib/python3.5/dist-packages/flask/json/__init__.py", line 179, in dumps
    rv = _json.dumps(obj, **kwargs)
  File "/usr/lib/python3.5/json/__init__.py", line 237, in dumps
    **kw).encode(obj)
  File "/usr/lib/python3.5/json/encoder.py", line 198, in encode
    chunks = self.iterencode(o, _one_shot=True)
  File "/usr/lib/python3.5/json/encoder.py", line 256, in iterencode
    return _iterencode(o, 0)
  File "/usr/local/lib/python3.5/dist-packages/flask/json/__init__.py", line 81, in default
    return _json.JSONEncoder.default(self, o)
  File "/usr/lib/python3.5/json/encoder.py", line 179, in default
    raise TypeError(repr(o) + " is not JSON serializable")
TypeError: {ImmutableMultiDict([]), None, 'GET'} is not JSON serializable
INFO:werkzeug:127.0.0.1 - - [17/Sep/2018 18:26:06] "GET /product/index HTTP/1.1" 500 -
INFO:werkzeug: * Running on http://127.0.0.1:5000/ (Press CTRL+C to quit)
ERROR:flask.app:Exception on /product/index [GET]
Traceback (most recent call last):
  File "/usr/local/lib/python3.5/dist-packages/flask/app.py", line 2292, in wsgi_app
    response = self.full_dispatch_request()
  File "/usr/local/lib/python3.5/dist-packages/flask/app.py", line 1815, in full_dispatch_request
    rv = self.handle_user_exception(e)
  File "/usr/local/lib/python3.5/dist-packages/flask/app.py", line 1718, in handle_user_exception
    reraise(exc_type, exc_value, tb)
  File "/usr/local/lib/python3.5/dist-packages/flask/_compat.py", line 35, in reraise
    raise value
  File "/usr/local/lib/python3.5/dist-packages/flask/app.py", line 1813, in full_dispatch_request
    rv = self.dispatch_request()
  File "/usr/local/lib/python3.5/dist-packages/flask/app.py", line 1799, in dispatch_request
    return self.view_functions[rule.endpoint](**req.view_args)
  File "app.py", line 21, in route
    return jsonify(response), 200
  File "/usr/local/lib/python3.5/dist-packages/flask/json/__init__.py", line 321, in jsonify
    dumps(data, indent=indent, separators=separators) + '\n',
  File "/usr/local/lib/python3.5/dist-packages/flask/json/__init__.py", line 179, in dumps
    rv = _json.dumps(obj, **kwargs)
  File "/usr/lib/python3.5/json/__init__.py", line 237, in dumps
    **kw).encode(obj)
  File "/usr/lib/python3.5/json/encoder.py", line 198, in encode
    chunks = self.iterencode(o, _one_shot=True)
  File "/usr/lib/python3.5/json/encoder.py", line 256, in iterencode
    return _iterencode(o, 0)
  File "/usr/local/lib/python3.5/dist-packages/flask/json/__init__.py", line 81, in default
    return _json.JSONEncoder.default(self, o)
  File "/usr/lib/python3.5/json/encoder.py", line 179, in default
    raise TypeError(repr(o) + " is not JSON serializable")
TypeError: {'GET', ImmutableMultiDict([]), None} is not JSON serializable
INFO:werkzeug:127.0.0.1 - - [17/Sep/2018 18:26:26] "GET /product/index HTTP/1.1" 500 -
ERROR:flask.app:Exception on /product/index [GET]
Traceback (most recent call last):
  File "/usr/local/lib/python3.5/dist-packages/flask/app.py", line 2292, in wsgi_app
    response = self.full_dispatch_request()
  File "/usr/local/lib/python3.5/dist-packages/flask/app.py", line 1815, in full_dispatch_request
    rv = self.handle_user_exception(e)
  File "/usr/local/lib/python3.5/dist-packages/flask/app.py", line 1718, in handle_user_exception
    reraise(exc_type, exc_value, tb)
  File "/usr/local/lib/python3.5/dist-packages/flask/_compat.py", line 35, in reraise
    raise value
  File "/usr/local/lib/python3.5/dist-packages/flask/app.py", line 1813, in full_dispatch_request
    rv = self.dispatch_request()
  File "/usr/local/lib/python3.5/dist-packages/flask/app.py", line 1799, in dispatch_request
    return self.view_functions[rule.endpoint](**req.view_args)
  File "app.py", line 21, in route
    return jsonify(response), 200
  File "/usr/local/lib/python3.5/dist-packages/flask/json/__init__.py", line 321, in jsonify
    dumps(data, indent=indent, separators=separators) + '\n',
  File "/usr/local/lib/python3.5/dist-packages/flask/json/__init__.py", line 179, in dumps
    rv = _json.dumps(obj, **kwargs)
  File "/usr/lib/python3.5/json/__init__.py", line 237, in dumps
    **kw).encode(obj)
  File "/usr/lib/python3.5/json/encoder.py", line 198, in encode
    chunks = self.iterencode(o, _one_shot=True)
  File "/usr/lib/python3.5/json/encoder.py", line 256, in iterencode
    return _iterencode(o, 0)
  File "/usr/local/lib/python3.5/dist-packages/flask/json/__init__.py", line 81, in default
    return _json.JSONEncoder.default(self, o)
  File "/usr/lib/python3.5/json/encoder.py", line 179, in default
    raise TypeError(repr(o) + " is not JSON serializable")
TypeError: {'GET', ImmutableMultiDict([]), None} is not JSON serializable
INFO:werkzeug:127.0.0.1 - - [17/Sep/2018 18:26:26] "GET /product/index HTTP/1.1" 500 -
INFO:werkzeug: * Running on http://127.0.0.1:5000/ (Press CTRL+C to quit)
ERROR:flask.app:Exception on /product/index [GET]
Traceback (most recent call last):
  File "/usr/local/lib/python3.5/dist-packages/flask/app.py", line 2292, in wsgi_app
    response = self.full_dispatch_request()
  File "/usr/local/lib/python3.5/dist-packages/flask/app.py", line 1815, in full_dispatch_request
    rv = self.handle_user_exception(e)
  File "/usr/local/lib/python3.5/dist-packages/flask/app.py", line 1718, in handle_user_exception
    reraise(exc_type, exc_value, tb)
  File "/usr/local/lib/python3.5/dist-packages/flask/_compat.py", line 35, in reraise
    raise value
  File "/usr/local/lib/python3.5/dist-packages/flask/app.py", line 1813, in full_dispatch_request
    rv = self.dispatch_request()
  File "/usr/local/lib/python3.5/dist-packages/flask/app.py", line 1799, in dispatch_request
    return self.view_functions[rule.endpoint](**req.view_args)
  File "app.py", line 21, in route
    return jsonify(response), 200
  File "/usr/local/lib/python3.5/dist-packages/flask/json/__init__.py", line 321, in jsonify
    dumps(data, indent=indent, separators=separators) + '\n',
  File "/usr/local/lib/python3.5/dist-packages/flask/json/__init__.py", line 179, in dumps
    rv = _json.dumps(obj, **kwargs)
  File "/usr/lib/python3.5/json/__init__.py", line 237, in dumps
    **kw).encode(obj)
  File "/usr/lib/python3.5/json/encoder.py", line 198, in encode
    chunks = self.iterencode(o, _one_shot=True)
  File "/usr/lib/python3.5/json/encoder.py", line 256, in iterencode
    return _iterencode(o, 0)
  File "/usr/local/lib/python3.5/dist-packages/flask/json/__init__.py", line 81, in default
    return _json.JSONEncoder.default(self, o)
  File "/usr/lib/python3.5/json/encoder.py", line 179, in default
    raise TypeError(repr(o) + " is not JSON serializable")
TypeError: {'GET', ImmutableMultiDict([]), None} is not JSON serializable
INFO:werkzeug:127.0.0.1 - - [17/Sep/2018 18:26:39] "GET /product/index HTTP/1.1" 500 -
INFO:werkzeug: * Running on http://127.0.0.1:5000/ (Press CTRL+C to quit)
INFO:werkzeug:127.0.0.1 - - [17/Sep/2018 18:26:46] "GET /product/index HTTP/1.1" 200 -
INFO:werkzeug: * Running on http://127.0.0.1:5000/ (Press CTRL+C to quit)
INFO:werkzeug:127.0.0.1 - - [17/Sep/2018 18:26:54] "GET /product/index HTTP/1.1" 200 -
INFO:werkzeug:127.0.0.1 - - [17/Sep/2018 18:26:55] "GET /product/index HTTP/1.1" 200 -
INFO:werkzeug:127.0.0.1 - - [17/Sep/2018 18:26:55] "GET /product/index HTTP/1.1" 200 -
INFO:werkzeug: * Running on http://127.0.0.1:5000/ (Press CTRL+C to quit)
ERROR:flask.app:Exception on /product/index [GET]
Traceback (most recent call last):
  File "/usr/local/lib/python3.5/dist-packages/flask/app.py", line 2292, in wsgi_app
    response = self.full_dispatch_request()
  File "/usr/local/lib/python3.5/dist-packages/flask/app.py", line 1816, in full_dispatch_request
    return self.finalize_request(rv)
  File "/usr/local/lib/python3.5/dist-packages/flask/app.py", line 1831, in finalize_request
    response = self.make_response(rv)
  File "/usr/local/lib/python3.5/dist-packages/flask/app.py", line 1957, in make_response
    'The view function did not return a valid response. The'
TypeError: The view function did not return a valid response. The function either returned None or ended without a return statement.
INFO:werkzeug:127.0.0.1 - - [17/Sep/2018 18:27:16] "GET /product/index HTTP/1.1" 500 -
ERROR:flask.app:Exception on /product/index [GET]
Traceback (most recent call last):
  File "/usr/local/lib/python3.5/dist-packages/flask/app.py", line 2292, in wsgi_app
    response = self.full_dispatch_request()
  File "/usr/local/lib/python3.5/dist-packages/flask/app.py", line 1816, in full_dispatch_request
    return self.finalize_request(rv)
  File "/usr/local/lib/python3.5/dist-packages/flask/app.py", line 1831, in finalize_request
    response = self.make_response(rv)
  File "/usr/local/lib/python3.5/dist-packages/flask/app.py", line 1957, in make_response
    'The view function did not return a valid response. The'
TypeError: The view function did not return a valid response. The function either returned None or ended without a return statement.
INFO:werkzeug:127.0.0.1 - - [17/Sep/2018 18:27:17] "GET /product/index HTTP/1.1" 500 -
ERROR:flask.app:Exception on /product/index [GET]
Traceback (most recent call last):
  File "/usr/local/lib/python3.5/dist-packages/flask/app.py", line 2292, in wsgi_app
    response = self.full_dispatch_request()
  File "/usr/local/lib/python3.5/dist-packages/flask/app.py", line 1816, in full_dispatch_request
    return self.finalize_request(rv)
  File "/usr/local/lib/python3.5/dist-packages/flask/app.py", line 1831, in finalize_request
    response = self.make_response(rv)
  File "/usr/local/lib/python3.5/dist-packages/flask/app.py", line 1957, in make_response
    'The view function did not return a valid response. The'
TypeError: The view function did not return a valid response. The function either returned None or ended without a return statement.
INFO:werkzeug:127.0.0.1 - - [17/Sep/2018 18:27:17] "GET /product/index HTTP/1.1" 500 -
ERROR:flask.app:Exception on /product/index [GET]
Traceback (most recent call last):
  File "/usr/local/lib/python3.5/dist-packages/flask/app.py", line 2292, in wsgi_app
    response = self.full_dispatch_request()
  File "/usr/local/lib/python3.5/dist-packages/flask/app.py", line 1816, in full_dispatch_request
    return self.finalize_request(rv)
  File "/usr/local/lib/python3.5/dist-packages/flask/app.py", line 1831, in finalize_request
    response = self.make_response(rv)
  File "/usr/local/lib/python3.5/dist-packages/flask/app.py", line 1957, in make_response
    'The view function did not return a valid response. The'
TypeError: The view function did not return a valid response. The function either returned None or ended without a return statement.
INFO:werkzeug:127.0.0.1 - - [17/Sep/2018 18:27:17] "GET /product/index HTTP/1.1" 500 -
ERROR:flask.app:Exception on /product/index [GET]
Traceback (most recent call last):
  File "/usr/local/lib/python3.5/dist-packages/flask/app.py", line 2292, in wsgi_app
    response = self.full_dispatch_request()
  File "/usr/local/lib/python3.5/dist-packages/flask/app.py", line 1816, in full_dispatch_request
    return self.finalize_request(rv)
  File "/usr/local/lib/python3.5/dist-packages/flask/app.py", line 1831, in finalize_request
    response = self.make_response(rv)
  File "/usr/local/lib/python3.5/dist-packages/flask/app.py", line 1957, in make_response
    'The view function did not return a valid response. The'
TypeError: The view function did not return a valid response. The function either returned None or ended without a return statement.
INFO:werkzeug:127.0.0.1 - - [17/Sep/2018 18:27:41] "GET /product/index HTTP/1.1" 500 -
INFO:werkzeug: * Running on http://127.0.0.1:5000/ (Press CTRL+C to quit)
INFO:werkzeug:127.0.0.1 - - [17/Sep/2018 18:27:44] "GET /product/index HTTP/1.1" 200 -
INFO:werkzeug: * Running on http://127.0.0.1:5000/ (Press CTRL+C to quit)
ERROR:flask.app:Exception on /product/index [GET]
Traceback (most recent call last):
  File "/usr/local/lib/python3.5/dist-packages/flask/app.py", line 2292, in wsgi_app
    response = self.full_dispatch_request()
  File "/usr/local/lib/python3.5/dist-packages/flask/app.py", line 1815, in full_dispatch_request
    rv = self.handle_user_exception(e)
  File "/usr/local/lib/python3.5/dist-packages/flask/app.py", line 1718, in handle_user_exception
    reraise(exc_type, exc_value, tb)
  File "/usr/local/lib/python3.5/dist-packages/flask/_compat.py", line 35, in reraise
    raise value
  File "/usr/local/lib/python3.5/dist-packages/flask/app.py", line 1813, in full_dispatch_request
    rv = self.dispatch_request()
  File "/usr/local/lib/python3.5/dist-packages/flask/app.py", line 1799, in dispatch_request
    return self.view_functions[rule.endpoint](**req.view_args)
  File "app.py", line 21, in route
    return jsonify(response), 200
  File "/usr/local/lib/python3.5/dist-packages/flask/json/__init__.py", line 321, in jsonify
    dumps(data, indent=indent, separators=separators) + '\n',
  File "/usr/local/lib/python3.5/dist-packages/flask/json/__init__.py", line 179, in dumps
    rv = _json.dumps(obj, **kwargs)
  File "/usr/lib/python3.5/json/__init__.py", line 237, in dumps
    **kw).encode(obj)
  File "/usr/lib/python3.5/json/encoder.py", line 198, in encode
    chunks = self.iterencode(o, _one_shot=True)
  File "/usr/lib/python3.5/json/encoder.py", line 256, in iterencode
    return _iterencode(o, 0)
  File "/usr/local/lib/python3.5/dist-packages/flask/json/__init__.py", line 81, in default
    return _json.JSONEncoder.default(self, o)
  File "/usr/lib/python3.5/json/encoder.py", line 179, in default
    raise TypeError(repr(o) + " is not JSON serializable")
TypeError: {'teste3', 'teste2', 'teste'} is not JSON serializable
INFO:werkzeug:127.0.0.1 - - [17/Sep/2018 18:28:22] "GET /product/index HTTP/1.1" 500 -
ERROR:flask.app:Exception on /product/index [GET]
Traceback (most recent call last):
  File "/usr/local/lib/python3.5/dist-packages/flask/app.py", line 2292, in wsgi_app
    response = self.full_dispatch_request()
  File "/usr/local/lib/python3.5/dist-packages/flask/app.py", line 1815, in full_dispatch_request
    rv = self.handle_user_exception(e)
  File "/usr/local/lib/python3.5/dist-packages/flask/app.py", line 1718, in handle_user_exception
    reraise(exc_type, exc_value, tb)
  File "/usr/local/lib/python3.5/dist-packages/flask/_compat.py", line 35, in reraise
    raise value
  File "/usr/local/lib/python3.5/dist-packages/flask/app.py", line 1813, in full_dispatch_request
    rv = self.dispatch_request()
  File "/usr/local/lib/python3.5/dist-packages/flask/app.py", line 1799, in dispatch_request
    return self.view_functions[rule.endpoint](**req.view_args)
  File "app.py", line 21, in route
    return jsonify(response), 200
  File "/usr/local/lib/python3.5/dist-packages/flask/json/__init__.py", line 321, in jsonify
    dumps(data, indent=indent, separators=separators) + '\n',
  File "/usr/local/lib/python3.5/dist-packages/flask/json/__init__.py", line 179, in dumps
    rv = _json.dumps(obj, **kwargs)
  File "/usr/lib/python3.5/json/__init__.py", line 237, in dumps
    **kw).encode(obj)
  File "/usr/lib/python3.5/json/encoder.py", line 198, in encode
    chunks = self.iterencode(o, _one_shot=True)
  File "/usr/lib/python3.5/json/encoder.py", line 256, in iterencode
    return _iterencode(o, 0)
  File "/usr/local/lib/python3.5/dist-packages/flask/json/__init__.py", line 81, in default
    return _json.JSONEncoder.default(self, o)
  File "/usr/lib/python3.5/json/encoder.py", line 179, in default
    raise TypeError(repr(o) + " is not JSON serializable")
TypeError: {'teste3', 'teste2', 'teste'} is not JSON serializable
INFO:werkzeug:127.0.0.1 - - [17/Sep/2018 18:28:23] "GET /product/index HTTP/1.1" 500 -
INFO:werkzeug: * Running on http://127.0.0.1:5000/ (Press CTRL+C to quit)
ERROR:flask.app:Exception on /product/index [GET]
Traceback (most recent call last):
  File "/usr/local/lib/python3.5/dist-packages/flask/app.py", line 2292, in wsgi_app
    response = self.full_dispatch_request()
  File "/usr/local/lib/python3.5/dist-packages/flask/app.py", line 1815, in full_dispatch_request
    rv = self.handle_user_exception(e)
  File "/usr/local/lib/python3.5/dist-packages/flask/app.py", line 1718, in handle_user_exception
    reraise(exc_type, exc_value, tb)
  File "/usr/local/lib/python3.5/dist-packages/flask/_compat.py", line 35, in reraise
    raise value
  File "/usr/local/lib/python3.5/dist-packages/flask/app.py", line 1813, in full_dispatch_request
    rv = self.dispatch_request()
  File "/usr/local/lib/python3.5/dist-packages/flask/app.py", line 1799, in dispatch_request
    return self.view_functions[rule.endpoint](**req.view_args)
  File "app.py", line 20, in route
    response = routing(request.method, controller, method, id, request.form)
  File "app.py", line 28, in routing
    return load_method(verb, controller, method, id, form)
  File "app.py", line 41, in load_method
    return getattr(controller, method)(verb, id, form)
  File "/home/fabio/www/python/controller/product.py", line 4, in index
    return jsonify({'teste', 'teste2', 'teste3'})
  File "/usr/local/lib/python3.5/dist-packages/flask/json/__init__.py", line 321, in jsonify
    dumps(data, indent=indent, separators=separators) + '\n',
  File "/usr/local/lib/python3.5/dist-packages/flask/json/__init__.py", line 179, in dumps
    rv = _json.dumps(obj, **kwargs)
  File "/usr/lib/python3.5/json/__init__.py", line 237, in dumps
    **kw).encode(obj)
  File "/usr/lib/python3.5/json/encoder.py", line 198, in encode
    chunks = self.iterencode(o, _one_shot=True)
  File "/usr/lib/python3.5/json/encoder.py", line 256, in iterencode
    return _iterencode(o, 0)
  File "/usr/local/lib/python3.5/dist-packages/flask/json/__init__.py", line 81, in default
    return _json.JSONEncoder.default(self, o)
  File "/usr/lib/python3.5/json/encoder.py", line 179, in default
    raise TypeError(repr(o) + " is not JSON serializable")
TypeError: {'teste2', 'teste3', 'teste'} is not JSON serializable
INFO:werkzeug:127.0.0.1 - - [17/Sep/2018 18:28:53] "GET /product/index HTTP/1.1" 500 -
ERROR:flask.app:Exception on /product/index [GET]
Traceback (most recent call last):
  File "/usr/local/lib/python3.5/dist-packages/flask/app.py", line 2292, in wsgi_app
    response = self.full_dispatch_request()
  File "/usr/local/lib/python3.5/dist-packages/flask/app.py", line 1815, in full_dispatch_request
    rv = self.handle_user_exception(e)
  File "/usr/local/lib/python3.5/dist-packages/flask/app.py", line 1718, in handle_user_exception
    reraise(exc_type, exc_value, tb)
  File "/usr/local/lib/python3.5/dist-packages/flask/_compat.py", line 35, in reraise
    raise value
  File "/usr/local/lib/python3.5/dist-packages/flask/app.py", line 1813, in full_dispatch_request
    rv = self.dispatch_request()
  File "/usr/local/lib/python3.5/dist-packages/flask/app.py", line 1799, in dispatch_request
    return self.view_functions[rule.endpoint](**req.view_args)
  File "app.py", line 20, in route
    response = routing(request.method, controller, method, id, request.form)
  File "app.py", line 28, in routing
    return load_method(verb, controller, method, id, form)
  File "app.py", line 41, in load_method
    return getattr(controller, method)(verb, id, form)
  File "/home/fabio/www/python/controller/product.py", line 4, in index
    return jsonify({'teste', 'teste2', 'teste3'})
  File "/usr/local/lib/python3.5/dist-packages/flask/json/__init__.py", line 321, in jsonify
    dumps(data, indent=indent, separators=separators) + '\n',
  File "/usr/local/lib/python3.5/dist-packages/flask/json/__init__.py", line 179, in dumps
    rv = _json.dumps(obj, **kwargs)
  File "/usr/lib/python3.5/json/__init__.py", line 237, in dumps
    **kw).encode(obj)
  File "/usr/lib/python3.5/json/encoder.py", line 198, in encode
    chunks = self.iterencode(o, _one_shot=True)
  File "/usr/lib/python3.5/json/encoder.py", line 256, in iterencode
    return _iterencode(o, 0)
  File "/usr/local/lib/python3.5/dist-packages/flask/json/__init__.py", line 81, in default
    return _json.JSONEncoder.default(self, o)
  File "/usr/lib/python3.5/json/encoder.py", line 179, in default
    raise TypeError(repr(o) + " is not JSON serializable")
TypeError: {'teste2', 'teste3', 'teste'} is not JSON serializable
INFO:werkzeug:127.0.0.1 - - [17/Sep/2018 18:28:54] "GET /product/index HTTP/1.1" 500 -
INFO:werkzeug: * Running on http://127.0.0.1:5000/ (Press CTRL+C to quit)
ERROR:flask.app:Exception on /product/index [GET]
Traceback (most recent call last):
  File "/usr/local/lib/python3.5/dist-packages/flask/app.py", line 2292, in wsgi_app
    response = self.full_dispatch_request()
  File "/usr/local/lib/python3.5/dist-packages/flask/app.py", line 1815, in full_dispatch_request
    rv = self.handle_user_exception(e)
  File "/usr/local/lib/python3.5/dist-packages/flask/app.py", line 1718, in handle_user_exception
    reraise(exc_type, exc_value, tb)
  File "/usr/local/lib/python3.5/dist-packages/flask/_compat.py", line 35, in reraise
    raise value
  File "/usr/local/lib/python3.5/dist-packages/flask/app.py", line 1813, in full_dispatch_request
    rv = self.dispatch_request()
  File "/usr/local/lib/python3.5/dist-packages/flask/app.py", line 1799, in dispatch_request
    return self.view_functions[rule.endpoint](**req.view_args)
  File "app.py", line 20, in route
    response = routing(request.method, controller, method, id, request.form)
  File "app.py", line 28, in routing
    return load_method(verb, controller, method, id, form)
  File "app.py", line 41, in load_method
    return getattr(controller, method)(verb, id, form)
  File "/home/fabio/www/python/controller/product.py", line 4, in index
    return jsonify({'teste', 'teste2', 'teste3'})
  File "/usr/local/lib/python3.5/dist-packages/flask/json/__init__.py", line 321, in jsonify
    dumps(data, indent=indent, separators=separators) + '\n',
  File "/usr/local/lib/python3.5/dist-packages/flask/json/__init__.py", line 179, in dumps
    rv = _json.dumps(obj, **kwargs)
  File "/usr/lib/python3.5/json/__init__.py", line 237, in dumps
    **kw).encode(obj)
  File "/usr/lib/python3.5/json/encoder.py", line 198, in encode
    chunks = self.iterencode(o, _one_shot=True)
  File "/usr/lib/python3.5/json/encoder.py", line 256, in iterencode
    return _iterencode(o, 0)
  File "/usr/local/lib/python3.5/dist-packages/flask/json/__init__.py", line 81, in default
    return _json.JSONEncoder.default(self, o)
  File "/usr/lib/python3.5/json/encoder.py", line 179, in default
    raise TypeError(repr(o) + " is not JSON serializable")
TypeError: {'teste', 'teste3', 'teste2'} is not JSON serializable
INFO:werkzeug:127.0.0.1 - - [17/Sep/2018 18:29:11] "GET /product/index HTTP/1.1" 500 -
INFO:werkzeug: * Running on http://127.0.0.1:5000/ (Press CTRL+C to quit)
ERROR:flask.app:Exception on /product/index [GET]
Traceback (most recent call last):
  File "/usr/local/lib/python3.5/dist-packages/flask/app.py", line 1974, in make_response
    rv = self.response_class.force_type(rv, request.environ)
  File "/usr/local/lib/python3.5/dist-packages/werkzeug/wrappers.py", line 921, in force_type
    response = BaseResponse(*_run_wsgi_app(response, environ))
  File "/usr/local/lib/python3.5/dist-packages/werkzeug/wrappers.py", line 59, in _run_wsgi_app
    return _run_wsgi_app(*args)
  File "/usr/local/lib/python3.5/dist-packages/werkzeug/test.py", line 923, in run_wsgi_app
    app_rv = app(environ, start_response)
TypeError: 'set' object is not callable

During handling of the above exception, another exception occurred:

Traceback (most recent call last):
  File "/usr/local/lib/python3.5/dist-packages/flask/app.py", line 2292, in wsgi_app
    response = self.full_dispatch_request()
  File "/usr/local/lib/python3.5/dist-packages/flask/app.py", line 1816, in full_dispatch_request
    return self.finalize_request(rv)
  File "/usr/local/lib/python3.5/dist-packages/flask/app.py", line 1831, in finalize_request
    response = self.make_response(rv)
  File "/usr/local/lib/python3.5/dist-packages/flask/app.py", line 1982, in make_response
    reraise(TypeError, new_error, sys.exc_info()[2])
  File "/usr/local/lib/python3.5/dist-packages/flask/_compat.py", line 34, in reraise
    raise value.with_traceback(tb)
  File "/usr/local/lib/python3.5/dist-packages/flask/app.py", line 1974, in make_response
    rv = self.response_class.force_type(rv, request.environ)
  File "/usr/local/lib/python3.5/dist-packages/werkzeug/wrappers.py", line 921, in force_type
    response = BaseResponse(*_run_wsgi_app(response, environ))
  File "/usr/local/lib/python3.5/dist-packages/werkzeug/wrappers.py", line 59, in _run_wsgi_app
    return _run_wsgi_app(*args)
  File "/usr/local/lib/python3.5/dist-packages/werkzeug/test.py", line 923, in run_wsgi_app
    app_rv = app(environ, start_response)
TypeError: 'set' object is not callable
The view function did not return a valid response. The return type must be a string, tuple, Response instance, or WSGI callable, but it was a set.
INFO:werkzeug:127.0.0.1 - - [17/Sep/2018 18:29:32] "GET /product/index HTTP/1.1" 500 -
ERROR:flask.app:Exception on /product/index [GET]
Traceback (most recent call last):
  File "/usr/local/lib/python3.5/dist-packages/flask/app.py", line 1974, in make_response
    rv = self.response_class.force_type(rv, request.environ)
  File "/usr/local/lib/python3.5/dist-packages/werkzeug/wrappers.py", line 921, in force_type
    response = BaseResponse(*_run_wsgi_app(response, environ))
  File "/usr/local/lib/python3.5/dist-packages/werkzeug/test.py", line 923, in run_wsgi_app
    app_rv = app(environ, start_response)
TypeError: 'set' object is not callable

During handling of the above exception, another exception occurred:

Traceback (most recent call last):
  File "/usr/local/lib/python3.5/dist-packages/flask/app.py", line 2292, in wsgi_app
    response = self.full_dispatch_request()
  File "/usr/local/lib/python3.5/dist-packages/flask/app.py", line 1816, in full_dispatch_request
    return self.finalize_request(rv)
  File "/usr/local/lib/python3.5/dist-packages/flask/app.py", line 1831, in finalize_request
    response = self.make_response(rv)
  File "/usr/local/lib/python3.5/dist-packages/flask/app.py", line 1982, in make_response
    reraise(TypeError, new_error, sys.exc_info()[2])
  File "/usr/local/lib/python3.5/dist-packages/flask/_compat.py", line 34, in reraise
    raise value.with_traceback(tb)
  File "/usr/local/lib/python3.5/dist-packages/flask/app.py", line 1974, in make_response
    rv = self.response_class.force_type(rv, request.environ)
  File "/usr/local/lib/python3.5/dist-packages/werkzeug/wrappers.py", line 921, in force_type
    response = BaseResponse(*_run_wsgi_app(response, environ))
  File "/usr/local/lib/python3.5/dist-packages/werkzeug/test.py", line 923, in run_wsgi_app
    app_rv = app(environ, start_response)
TypeError: 'set' object is not callable
The view function did not return a valid response. The return type must be a string, tuple, Response instance, or WSGI callable, but it was a set.
INFO:werkzeug:127.0.0.1 - - [17/Sep/2018 18:29:33] "GET /product/index HTTP/1.1" 500 -
ERROR:flask.app:Exception on /product/index [GET]
Traceback (most recent call last):
  File "/usr/local/lib/python3.5/dist-packages/flask/app.py", line 1974, in make_response
    rv = self.response_class.force_type(rv, request.environ)
  File "/usr/local/lib/python3.5/dist-packages/werkzeug/wrappers.py", line 921, in force_type
    response = BaseResponse(*_run_wsgi_app(response, environ))
  File "/usr/local/lib/python3.5/dist-packages/werkzeug/test.py", line 923, in run_wsgi_app
    app_rv = app(environ, start_response)
TypeError: 'set' object is not callable

During handling of the above exception, another exception occurred:

Traceback (most recent call last):
  File "/usr/local/lib/python3.5/dist-packages/flask/app.py", line 2292, in wsgi_app
    response = self.full_dispatch_request()
  File "/usr/local/lib/python3.5/dist-packages/flask/app.py", line 1816, in full_dispatch_request
    return self.finalize_request(rv)
  File "/usr/local/lib/python3.5/dist-packages/flask/app.py", line 1831, in finalize_request
    response = self.make_response(rv)
  File "/usr/local/lib/python3.5/dist-packages/flask/app.py", line 1982, in make_response
    reraise(TypeError, new_error, sys.exc_info()[2])
  File "/usr/local/lib/python3.5/dist-packages/flask/_compat.py", line 34, in reraise
    raise value.with_traceback(tb)
  File "/usr/local/lib/python3.5/dist-packages/flask/app.py", line 1974, in make_response
    rv = self.response_class.force_type(rv, request.environ)
  File "/usr/local/lib/python3.5/dist-packages/werkzeug/wrappers.py", line 921, in force_type
    response = BaseResponse(*_run_wsgi_app(response, environ))
  File "/usr/local/lib/python3.5/dist-packages/werkzeug/test.py", line 923, in run_wsgi_app
    app_rv = app(environ, start_response)
TypeError: 'set' object is not callable
The view function did not return a valid response. The return type must be a string, tuple, Response instance, or WSGI callable, but it was a set.
INFO:werkzeug:127.0.0.1 - - [17/Sep/2018 18:29:33] "GET /product/index HTTP/1.1" 500 -
ERROR:flask.app:Exception on /product/index [GET]
Traceback (most recent call last):
  File "/usr/local/lib/python3.5/dist-packages/flask/app.py", line 1974, in make_response
    rv = self.response_class.force_type(rv, request.environ)
  File "/usr/local/lib/python3.5/dist-packages/werkzeug/wrappers.py", line 921, in force_type
    response = BaseResponse(*_run_wsgi_app(response, environ))
  File "/usr/local/lib/python3.5/dist-packages/werkzeug/test.py", line 923, in run_wsgi_app
    app_rv = app(environ, start_response)
TypeError: 'set' object is not callable

During handling of the above exception, another exception occurred:

Traceback (most recent call last):
  File "/usr/local/lib/python3.5/dist-packages/flask/app.py", line 2292, in wsgi_app
    response = self.full_dispatch_request()
  File "/usr/local/lib/python3.5/dist-packages/flask/app.py", line 1816, in full_dispatch_request
    return self.finalize_request(rv)
  File "/usr/local/lib/python3.5/dist-packages/flask/app.py", line 1831, in finalize_request
    response = self.make_response(rv)
  File "/usr/local/lib/python3.5/dist-packages/flask/app.py", line 1982, in make_response
    reraise(TypeError, new_error, sys.exc_info()[2])
  File "/usr/local/lib/python3.5/dist-packages/flask/_compat.py", line 34, in reraise
    raise value.with_traceback(tb)
  File "/usr/local/lib/python3.5/dist-packages/flask/app.py", line 1974, in make_response
    rv = self.response_class.force_type(rv, request.environ)
  File "/usr/local/lib/python3.5/dist-packages/werkzeug/wrappers.py", line 921, in force_type
    response = BaseResponse(*_run_wsgi_app(response, environ))
  File "/usr/local/lib/python3.5/dist-packages/werkzeug/test.py", line 923, in run_wsgi_app
    app_rv = app(environ, start_response)
TypeError: 'set' object is not callable
The view function did not return a valid response. The return type must be a string, tuple, Response instance, or WSGI callable, but it was a set.
INFO:werkzeug:127.0.0.1 - - [17/Sep/2018 18:29:33] "GET /product/index HTTP/1.1" 500 -
ERROR:flask.app:Exception on /product/index [GET]
Traceback (most recent call last):
  File "/usr/local/lib/python3.5/dist-packages/flask/app.py", line 1974, in make_response
    rv = self.response_class.force_type(rv, request.environ)
  File "/usr/local/lib/python3.5/dist-packages/werkzeug/wrappers.py", line 921, in force_type
    response = BaseResponse(*_run_wsgi_app(response, environ))
  File "/usr/local/lib/python3.5/dist-packages/werkzeug/test.py", line 923, in run_wsgi_app
    app_rv = app(environ, start_response)
TypeError: 'set' object is not callable

During handling of the above exception, another exception occurred:

Traceback (most recent call last):
  File "/usr/local/lib/python3.5/dist-packages/flask/app.py", line 2292, in wsgi_app
    response = self.full_dispatch_request()
  File "/usr/local/lib/python3.5/dist-packages/flask/app.py", line 1816, in full_dispatch_request
    return self.finalize_request(rv)
  File "/usr/local/lib/python3.5/dist-packages/flask/app.py", line 1831, in finalize_request
    response = self.make_response(rv)
  File "/usr/local/lib/python3.5/dist-packages/flask/app.py", line 1982, in make_response
    reraise(TypeError, new_error, sys.exc_info()[2])
  File "/usr/local/lib/python3.5/dist-packages/flask/_compat.py", line 34, in reraise
    raise value.with_traceback(tb)
  File "/usr/local/lib/python3.5/dist-packages/flask/app.py", line 1974, in make_response
    rv = self.response_class.force_type(rv, request.environ)
  File "/usr/local/lib/python3.5/dist-packages/werkzeug/wrappers.py", line 921, in force_type
    response = BaseResponse(*_run_wsgi_app(response, environ))
  File "/usr/local/lib/python3.5/dist-packages/werkzeug/test.py", line 923, in run_wsgi_app
    app_rv = app(environ, start_response)
TypeError: 'set' object is not callable
The view function did not return a valid response. The return type must be a string, tuple, Response instance, or WSGI callable, but it was a set.
INFO:werkzeug:127.0.0.1 - - [17/Sep/2018 18:29:33] "GET /product/index HTTP/1.1" 500 -
ERROR:flask.app:Exception on /product/index [GET]
Traceback (most recent call last):
  File "/usr/local/lib/python3.5/dist-packages/flask/app.py", line 1974, in make_response
    rv = self.response_class.force_type(rv, request.environ)
  File "/usr/local/lib/python3.5/dist-packages/werkzeug/wrappers.py", line 921, in force_type
    response = BaseResponse(*_run_wsgi_app(response, environ))
  File "/usr/local/lib/python3.5/dist-packages/werkzeug/test.py", line 923, in run_wsgi_app
    app_rv = app(environ, start_response)
TypeError: 'set' object is not callable

During handling of the above exception, another exception occurred:

Traceback (most recent call last):
  File "/usr/local/lib/python3.5/dist-packages/flask/app.py", line 2292, in wsgi_app
    response = self.full_dispatch_request()
  File "/usr/local/lib/python3.5/dist-packages/flask/app.py", line 1816, in full_dispatch_request
    return self.finalize_request(rv)
  File "/usr/local/lib/python3.5/dist-packages/flask/app.py", line 1831, in finalize_request
    response = self.make_response(rv)
  File "/usr/local/lib/python3.5/dist-packages/flask/app.py", line 1982, in make_response
    reraise(TypeError, new_error, sys.exc_info()[2])
  File "/usr/local/lib/python3.5/dist-packages/flask/_compat.py", line 34, in reraise
    raise value.with_traceback(tb)
  File "/usr/local/lib/python3.5/dist-packages/flask/app.py", line 1974, in make_response
    rv = self.response_class.force_type(rv, request.environ)
  File "/usr/local/lib/python3.5/dist-packages/werkzeug/wrappers.py", line 921, in force_type
    response = BaseResponse(*_run_wsgi_app(response, environ))
  File "/usr/local/lib/python3.5/dist-packages/werkzeug/test.py", line 923, in run_wsgi_app
    app_rv = app(environ, start_response)
TypeError: 'set' object is not callable
The view function did not return a valid response. The return type must be a string, tuple, Response instance, or WSGI callable, but it was a set.
INFO:werkzeug:127.0.0.1 - - [17/Sep/2018 18:29:34] "GET /product/index HTTP/1.1" 500 -
ERROR:flask.app:Exception on /product/index [GET]
Traceback (most recent call last):
  File "/usr/local/lib/python3.5/dist-packages/flask/app.py", line 1974, in make_response
    rv = self.response_class.force_type(rv, request.environ)
  File "/usr/local/lib/python3.5/dist-packages/werkzeug/wrappers.py", line 921, in force_type
    response = BaseResponse(*_run_wsgi_app(response, environ))
  File "/usr/local/lib/python3.5/dist-packages/werkzeug/test.py", line 923, in run_wsgi_app
    app_rv = app(environ, start_response)
TypeError: 'set' object is not callable

During handling of the above exception, another exception occurred:

Traceback (most recent call last):
  File "/usr/local/lib/python3.5/dist-packages/flask/app.py", line 2292, in wsgi_app
    response = self.full_dispatch_request()
  File "/usr/local/lib/python3.5/dist-packages/flask/app.py", line 1816, in full_dispatch_request
    return self.finalize_request(rv)
  File "/usr/local/lib/python3.5/dist-packages/flask/app.py", line 1831, in finalize_request
    response = self.make_response(rv)
  File "/usr/local/lib/python3.5/dist-packages/flask/app.py", line 1982, in make_response
    reraise(TypeError, new_error, sys.exc_info()[2])
  File "/usr/local/lib/python3.5/dist-packages/flask/_compat.py", line 34, in reraise
    raise value.with_traceback(tb)
  File "/usr/local/lib/python3.5/dist-packages/flask/app.py", line 1974, in make_response
    rv = self.response_class.force_type(rv, request.environ)
  File "/usr/local/lib/python3.5/dist-packages/werkzeug/wrappers.py", line 921, in force_type
    response = BaseResponse(*_run_wsgi_app(response, environ))
  File "/usr/local/lib/python3.5/dist-packages/werkzeug/test.py", line 923, in run_wsgi_app
    app_rv = app(environ, start_response)
TypeError: 'set' object is not callable
The view function did not return a valid response. The return type must be a string, tuple, Response instance, or WSGI callable, but it was a set.
INFO:werkzeug:127.0.0.1 - - [17/Sep/2018 18:29:34] "GET /product/index HTTP/1.1" 500 -
INFO:werkzeug: * Running on http://127.0.0.1:5000/ (Press CTRL+C to quit)
ERROR:flask.app:Exception on /product/index [GET]
Traceback (most recent call last):
  File "/usr/local/lib/python2.7/dist-packages/flask/app.py", line 2292, in wsgi_app
    response = self.full_dispatch_request()
  File "/usr/local/lib/python2.7/dist-packages/flask/app.py", line 1816, in full_dispatch_request
    return self.finalize_request(rv)
  File "/usr/local/lib/python2.7/dist-packages/flask/app.py", line 1831, in finalize_request
    response = self.make_response(rv)
  File "/usr/local/lib/python2.7/dist-packages/flask/app.py", line 1982, in make_response
    reraise(TypeError, new_error, sys.exc_info()[2])
  File "/usr/local/lib/python2.7/dist-packages/flask/app.py", line 1974, in make_response
    rv = self.response_class.force_type(rv, request.environ)
  File "/usr/local/lib/python2.7/dist-packages/werkzeug/wrappers.py", line 921, in force_type
    response = BaseResponse(*_run_wsgi_app(response, environ))
  File "/usr/local/lib/python2.7/dist-packages/werkzeug/wrappers.py", line 59, in _run_wsgi_app
    return _run_wsgi_app(*args)
  File "/usr/local/lib/python2.7/dist-packages/werkzeug/test.py", line 923, in run_wsgi_app
    app_rv = app(environ, start_response)
TypeError: 'set' object is not callable
The view function did not return a valid response. The return type must be a string, tuple, Response instance, or WSGI callable, but it was a set.
INFO:werkzeug:127.0.0.1 - - [17/Sep/2018 18:30:02] "GET /product/index HTTP/1.1" 500 -
INFO:werkzeug: * Running on http://127.0.0.1:5000/ (Press CTRL+C to quit)
ERROR:flask.app:Exception on /product/index [GET]
Traceback (most recent call last):
  File "/usr/local/lib/python2.7/dist-packages/flask/app.py", line 2292, in wsgi_app
    response = self.full_dispatch_request()
  File "/usr/local/lib/python2.7/dist-packages/flask/app.py", line 1815, in full_dispatch_request
    rv = self.handle_user_exception(e)
  File "/usr/local/lib/python2.7/dist-packages/flask/app.py", line 1718, in handle_user_exception
    reraise(exc_type, exc_value, tb)
  File "/usr/local/lib/python2.7/dist-packages/flask/app.py", line 1813, in full_dispatch_request
    rv = self.dispatch_request()
  File "/usr/local/lib/python2.7/dist-packages/flask/app.py", line 1799, in dispatch_request
    return self.view_functions[rule.endpoint](**req.view_args)
  File "app.py", line 20, in route
    response = routing(request.method, controller, method, id, request.form)
  File "app.py", line 28, in routing
    return load_method(verb, controller, method, id, form)
  File "app.py", line 41, in load_method
    return getattr(controller, method)(verb, id, form)
  File "/home/fabio/www/python/controller/product.py", line 4, in index
    return jsonify({'teste', 'teste2', 'teste3'})
  File "/usr/local/lib/python2.7/dist-packages/flask/json/__init__.py", line 321, in jsonify
    dumps(data, indent=indent, separators=separators) + '\n',
  File "/usr/local/lib/python2.7/dist-packages/flask/json/__init__.py", line 179, in dumps
    rv = _json.dumps(obj, **kwargs)
  File "/usr/lib/python2.7/json/__init__.py", line 251, in dumps
    sort_keys=sort_keys, **kw).encode(obj)
  File "/usr/lib/python2.7/json/encoder.py", line 209, in encode
    chunks = list(chunks)
  File "/usr/lib/python2.7/json/encoder.py", line 442, in _iterencode
    o = _default(o)
  File "/usr/local/lib/python2.7/dist-packages/flask/json/__init__.py", line 81, in default
    return _json.JSONEncoder.default(self, o)
  File "/usr/lib/python2.7/json/encoder.py", line 184, in default
    raise TypeError(repr(o) + " is not JSON serializable")
TypeError: set(['teste', 'teste3', 'teste2']) is not JSON serializable
INFO:werkzeug:127.0.0.1 - - [17/Sep/2018 18:30:34] "GET /product/index HTTP/1.1" 500 -
INFO:werkzeug: * Running on http://127.0.0.1:5000/ (Press CTRL+C to quit)
INFO:werkzeug:127.0.0.1 - - [17/Sep/2018 18:30:52] "GET /product/index HTTP/1.1" 200 -
INFO:werkzeug: * Running on http://127.0.0.1:5000/ (Press CTRL+C to quit)
ERROR:flask.app:Exception on /product/index [GET]
Traceback (most recent call last):
  File "/usr/local/lib/python2.7/dist-packages/flask/app.py", line 2292, in wsgi_app
    response = self.full_dispatch_request()
  File "/usr/local/lib/python2.7/dist-packages/flask/app.py", line 1815, in full_dispatch_request
    rv = self.handle_user_exception(e)
  File "/usr/local/lib/python2.7/dist-packages/flask/app.py", line 1718, in handle_user_exception
    reraise(exc_type, exc_value, tb)
  File "/usr/local/lib/python2.7/dist-packages/flask/app.py", line 1813, in full_dispatch_request
    rv = self.dispatch_request()
  File "/usr/local/lib/python2.7/dist-packages/flask/app.py", line 1799, in dispatch_request
    return self.view_functions[rule.endpoint](**req.view_args)
  File "app.py", line 20, in route
    response = routing(request.method, controller, method, id, request.form)
  File "app.py", line 28, in routing
    return load_method(verb, controller, method, id, form)
  File "app.py", line 41, in load_method
    return getattr(controller, method)(verb, id, form)
TypeError: slice indices must be integers or None or have an __index__ method
INFO:werkzeug:127.0.0.1 - - [17/Sep/2018 18:31:20] "GET /product/index HTTP/1.1" 500 -
